<sdf version="1.7">
  <world name="world">
    <scene>
      <ambient>0.8 0.8 0.8 1.0</ambient>
      <background>0 0 0</background>
      <grid>false</grid>
    </scene>
    <include>
      <uri>model://sun</uri>
    </include>
    <gui>
      <camera name="gui_camera">
        <pose>4.498780228712349 -25.262026824700456 10 0 0.6 1.57</pose>
      </camera>
      <plugin name="toggle_charging" filename="libtoggle_charging.so" />
      <plugin name="toggle_floors" filename="libtoggle_floors.so">
        <floor name="L1" model_name="Floorplan_L1">
          <model name="OpenRobotics/Sofa" />
          <model name="OpenRobotics/DigitalKiosk" />
          <model name="Door1" />
        </floor>
      </plugin>
    </gui>
    <include>
      <name>OpenRobotics/Sofa</name>
      <uri>model://Sofa</uri>
      <pose>4.913491521965666 -6.381184062824654 0.0 0 0 1.5978</pose>
      <static>True</static>
    </include>
    <include>
      <name>OpenRobotics/DigitalKiosk</name>
      <uri>model://DigitalKiosk</uri>
      <pose>0.7045469769174751 -5.132882611142735 0.0 0 0 0.0</pose>
      <static>True</static>
    </include>
    <model name="Door1">
      <pose>8.930374146440238 -5.396955122925636 0.0 0 0 1.5626281948119596</pose>
      <link name="right">
        <pose>0 0 1.11 0 0 0</pose>
        <visual name="right_visual">
          <geometry>
            <box>
              <size>3.9110329819682383 0.03 2.2</size>
            </box>
          </geometry>
          <material>
            <ambient>0.5 0.25 0 0.6</ambient>
            <diffuse>0.5 0.25 0 0.6</diffuse>
          </material>
        </visual>
        <collision name="right_collision">
          <geometry>
            <box>
              <size>3.9110329819682383 0.03 2.2</size>
            </box>
          </geometry>
          <surface>
            <contact>
              <collide_bitmask>0x02</collide_bitmask>
            </contact>
          </surface>
        </collision>
        <inertial>
          <mass>50.0</mass>
          <inertia>
            <ixx>20.17041666666667</ixx>
            <iyy>83.90074577518072</iyy>
            <izz>63.73782910851405</izz>
          </inertia>
        </inertial>
      </link>
      <joint name="right_joint" type="revolute">
        <parent>world</parent>
        <child>right</child>
        <axis>
          <xyz>0 0 -1</xyz>
          <limit>
            <lower>0</lower>
            <upper>1.57</upper>
          </limit>
        </axis>
        <pose>1.960516490984119 0 0 0 0 0</pose>
      </joint>
      <plugin name="door" filename="libdoor.so">
        <v_max_door>0.5</v_max_door>
        <a_max_door>0.3</a_max_door>
        <a_nom_door>0.15</a_nom_door>
        <dx_min_door>0.01</dx_min_door>
        <f_max_door>500.0</f_max_door>
        <door name="Door1" type="SwingDoor" left_joint_name="empty_joint" right_joint_name="right_joint" />
      </plugin>
    </model>
    <include>
      <name>Floorplan_L1</name>
      <uri>model://Floorplan_L1</uri>
      <pose>0 0 0.0 0 0 0</pose>
    </include>
    <rmf_charger_waypoints name="charger_waypoints">
      <rmf_vertex name="Point2" x="3.041064602454435" y="-2.9083590092543052" level="L1" />
      <rmf_vertex name="Point1" x="6.705901060575105" y="-2.860368787122549" level="L1" />
      <rmf_vertex name="Point3" x="6.7378777033218435" y="-7.741479538155104" level="L1" />
      <rmf_vertex name="Point4" x="3.1370955627412433" y="-7.741479538155104" level="L1" />
    </rmf_charger_waypoints>
  </world>
</sdf>
